
  var hasError = false;
  var caughtError = null; // Used by event system to capture/rethrow the first error.

  var hasRethrowError = false;
  var rethrowError = null;
  var reporter = {
    onError: function (error) {
      hasError = true;
      caughtError = error;
    }
  };
  /**
   * Call a function while guarding against errors that happens within it.
   * Returns an error if it throws, otherwise null.
   *
   * In production, this is implemented using a try-catch. The reason we don't
   * use a try-catch directly is so that we can swap out a different
   * implementation in DEV mode.
   *
   * @param {String} name of the guard to use for logging or debugging
   * @param {Function} func The function to invoke
   * @param {*} context The context to use when calling the function
   * @param {...*} args Arguments for function
   */

  function invokeGuardedCallback(name, func, context, a, b, c, d, e, f) {
    hasError = false;
    caughtError = null;
    invokeGuardedCallbackImpl$1.apply(reporter, arguments);
  }
  /**
   * Same as invokeGuardedCallback, but instead of returning an error, it stores
   * it in a global so it can be rethrown by `rethrowCaughtError` later.
   * TODO: See if caughtError and rethrowError can be unified.
   *
   * @param {String} name of the guard to use for logging or debugging
   * @param {Function} func The function to invoke
   * @param {*} context The context to use when calling the function
   * @param {...*} args Arguments for function
   */

  function invokeGuardedCallbackAndCatchFirstError(name, func, context, a, b, c, d, e, f) {
    invokeGuardedCallback.apply(this, arguments);

    if (hasError) {
      var error = clearCaughtError();

      if (!hasRethrowError) {
        hasRethrowError = true;
        rethrowError = error;
      }
    }
  }
  /**
   * During execution of guarded functions we will capture the first error which
   * we will rethrow to be handled by the top level error handler.
   */

  function rethrowCaughtError() {
    if (hasRethrowError) {
      var error = rethrowError;
      hasRethrowError = false;
      rethrowError = null;
      throw error;
    }
  }
  function hasCaughtError() {
    return hasError;
  }
  function clearCaughtError() {
    if (hasError) {
      var error = caughtError;
      hasError = false;
      caughtError = null;
      return error;
    } else {
      throw new Error('clearCaughtError was called but no error was captured. This error ' + 'is likely caused by a bug in React. Please file an issue.');
    }
  }